<?xml version="1.0"?>
<robot name="straddle_carrier" xmlns:xacro="http://www.ros.org/wiki/xacro">

  <!-- ── Parameters ─────────────────────────────────────────────────────── -->
  <xacro:property name="portal_width"   value="9.0"/>   <!-- m, outer span -->
  <xacro:property name="portal_length"  value="6.0"/>   <!-- m, front-rear -->
  <xacro:property name="portal_height"  value="14.0"/>  <!-- m, top of frame -->
  <xacro:property name="beam_thickness" value="0.5"/>
  <xacro:property name="wheel_radius"   value="0.75"/>
  <xacro:property name="wheel_width"    value="0.45"/>
  <xacro:property name="mass_body"      value="40000"/>  <!-- kg -->
  <xacro:property name="mass_wheel"     value="500"/>

  <!-- ── Inertia macros ─────────────────────────────────────────────────── -->
  <xacro:macro name="box_inertia" params="m x y z">
    <inertial>
      <mass value="${m}"/>
      <inertia
        ixx="${m*(y*y+z*z)/12}" ixy="0" ixz="0"
        iyy="${m*(x*x+z*z)/12}" iyz="0"
        izz="${m*(x*x+y*y)/12}"/>
    </inertial>
  </xacro:macro>

  <xacro:macro name="cylinder_inertia" params="m r h">
    <inertial>
      <mass value="${m}"/>
      <inertia
        ixx="${m*(3*r*r+h*h)/12}" ixy="0" ixz="0"
        iyy="${m*(3*r*r+h*h)/12}" iyz="0"
        izz="${m*r*r/2}"/>
    </inertial>
  </xacro:macro>

  <!-- ── Base footprint ─────────────────────────────────────────────────── -->
  <link name="base_footprint"/>

  <joint name="base_footprint_joint" type="fixed">
    <parent link="base_footprint"/>
    <child  link="base_link"/>
    <origin xyz="0 0 ${wheel_radius}" rpy="0 0 0"/>
  </joint>

  <!-- ── Portal frame body (simplified as three beams) ─────────────────── -->
  <link name="base_link">
    <xacro:box_inertia m="${mass_body}"
      x="${portal_length}" y="${portal_width}" z="${beam_thickness}"/>
    <!-- Top beam -->
    <visual>
      <origin xyz="0 0 ${portal_height - beam_thickness/2}"/>
      <geometry>
        <box size="${portal_length} ${portal_width} ${beam_thickness}"/>
      </geometry>
      <material name="yellow"><color rgba="0.9 0.8 0.0 1"/></material>
    </visual>
    <!-- Left leg -->
    <visual>
      <origin xyz="0 ${portal_width/2 - beam_thickness/2} ${portal_height/2}"/>
      <geometry>
        <box size="${portal_length} ${beam_thickness} ${portal_height}"/>
      </geometry>
      <material name="yellow"/>
    </visual>
    <!-- Right leg -->
    <visual>
      <origin xyz="0 ${-(portal_width/2 - beam_thickness/2)} ${portal_height/2}"/>
      <geometry>
        <box size="${portal_length} ${beam_thickness} ${portal_height}"/>
      </geometry>
      <material name="yellow"/>
    </visual>
    <collision>
      <origin xyz="0 0 ${portal_height/2}"/>
      <geometry>
        <box size="${portal_length} ${portal_width} ${portal_height}"/>
      </geometry>
    </collision>
  </link>

  <!-- ── Wheel macro ────────────────────────────────────────────────────── -->
  <!--
    pos: FR=front-right, FL=front-left, RR=rear-right, RL=rear-left
    x_sign: +1 front / -1 rear
    y_sign: +1 left  / -1 right (ROS convention)
  -->
  <xacro:macro name="wheel" params="name x_sign y_sign">
    <link name="${name}_wheel_link">
      <xacro:cylinder_inertia m="${mass_wheel}" r="${wheel_radius}" h="${wheel_width}"/>
      <visual>
        <geometry>
          <cylinder radius="${wheel_radius}" length="${wheel_width}"/>
        </geometry>
        <material name="dark"><color rgba="0.2 0.2 0.2 1"/></material>
      </visual>
      <collision>
        <geometry>
          <cylinder radius="${wheel_radius}" length="${wheel_width}"/>
        </geometry>
      </collision>
    </link>

    <joint name="${name}_wheel_joint" type="continuous">
      <parent link="base_link"/>
      <child  link="${name}_wheel_link"/>
      <origin
        xyz="${x_sign * portal_length/2} ${y_sign * portal_width/2} ${-wheel_radius}"
        rpy="${pi/2} 0 0"/>
      <axis xyz="0 0 1"/>
    </joint>

    <!-- Gazebo Harmonic friction/contact -->
    <gazebo reference="${name}_wheel_link">
      <mu1>1.0</mu1>
      <mu2>1.0</mu2>
      <kp>1e6</kp>
      <kd>100</kd>
    </gazebo>
  </xacro:macro>

  <xacro:wheel name="front_left"  x_sign="1"  y_sign="1"/>
  <xacro:wheel name="front_right" x_sign="1"  y_sign="-1"/>
  <xacro:wheel name="rear_left"   x_sign="-1" y_sign="1"/>
  <xacro:wheel name="rear_right"  x_sign="-1" y_sign="-1"/>

  <!-- ── Hoist (simplified rigid link for now) ──────────────────────────── -->
  <link name="hoist_link">
    <visual>
      <geometry><box size="${portal_length - 1.0} ${portal_width - 2.0} 0.3"/></geometry>
      <material name="gray"><color rgba="0.5 0.5 0.5 1"/></material>
    </visual>
    <inertial>
      <mass value="2000"/>
      <inertia ixx="1" ixy="0" ixz="0" iyy="1" iyz="0" izz="1"/>
    </inertial>
  </link>

  <joint name="hoist_joint" type="prismatic">
    <parent link="base_link"/>
    <child  link="hoist_link"/>
    <origin xyz="0 0 ${portal_height * 0.6}"/>
    <axis xyz="0 0 1"/>
    <limit lower="0" upper="${portal_height * 0.35}" effort="500000" velocity="0.2"/>
  </joint>

  <!-- ── Gazebo differential drive plugin ──────────────────────────────── -->
  <gazebo>
    <plugin filename="gz-sim-diff-drive-system"
            name="gz::sim::systems::DiffDrive">
      <left_joint>front_left_wheel_joint</left_joint>
      <left_joint>rear_left_wheel_joint</left_joint>
      <right_joint>front_right_wheel_joint</right_joint>
      <right_joint>rear_right_wheel_joint</right_joint>
      <wheel_separation>${portal_width}</wheel_separation>
      <wheel_radius>${wheel_radius}</wheel_radius>
      <odom_publish_frequency>50</odom_publish_frequency>
      <topic>cmd_vel</topic>
      <odom_topic>odom</odom_topic>
      <tf_topic>tf</tf_topic>
      <frame_id>odom</frame_id>
      <child_frame_id>base_footprint</child_frame_id>
      <max_linear_acceleration>0.5</max_linear_acceleration>
    </plugin>

    <plugin filename="gz-sim-joint-state-publisher-system"
            name="gz::sim::systems::JointStatePublisher">
      <topic>joint_states</topic>
    </plugin>
  </gazebo>

</robot>
